<?xml version="1.0"?>
<robot name="C:/mySciebo/_EMR25/github/emr25/urdf/UR3e.urdf" xmlns:xacro="http://ros.org/wiki/xacro">
  <link name="base_link">
    <visual>
      <origin xyz="0 0 0.045" rpy="-3.141592 0 0"/>
      <geometry>
        <cylinder radius="0.064" length="0.09"/>
      </geometry>
    </visual>
    <collision>
      <origin xyz="0 0 0.045" rpy="-3.141592 0 0"/>
      <geometry>
        <cylinder radius="0.064" length="0.09"/>
      </geometry>
    </collision>
  </link>
  <joint name="shoulder_pan_joint" type="revolute">
    <parent link="base_link"/>
    <child link="shoulder_link"/>
    <axis xyz="0 0 1"/>
    <limit effort="330" lower="-6.28319" upper="6.28319" velocity="3.14"/>
    <origin xyz="0 0 0.152" rpy="0 0 -0.669947"/>
  </joint>
  <link name="shoulder_link">
    <visual>
      <origin xyz="0 0 -0.003" rpy="-3.141592 0 0"/>
      <geometry>
        <cylinder radius="0.046" length="0.121"/>
      </geometry>
    </visual>
    <collision>
      <origin xyz="0 0 -0.003" rpy="-3.141592 0 0"/>
      <geometry>
        <cylinder radius="0.046" length="0.121"/>
      </geometry>
    </collision>
    <visual>
      <origin xyz="0 0.03 0" rpy="-1.570796 0 0"/>
      <geometry>
        <cylinder radius="0.045" length="0.066"/>
      </geometry>
    </visual>
    <collision>
      <origin xyz="0 0.03 0" rpy="-1.570796 0 0"/>
      <geometry>
        <cylinder radius="0.045" length="0.066"/>
      </geometry>
    </collision>
  </link>
  <joint name="shoulder_lift_joint" type="revolute">
    <parent link="shoulder_link"/>
    <child link="upper_arm_link"/>
    <axis xyz="0 1 0"/>
    <limit effort="330" lower="-6.28319" upper="6.28319" velocity="3.14"/>
    <origin xyz="0 0.12 0" rpy="0 -0.48923 0"/>
  </joint>
  <link name="upper_arm_link">
    <visual>
      <origin xyz="0 0 0.035" rpy="-3.141592 0 0"/>
      <geometry>
        <cylinder radius="0.046" length="0.073"/>
      </geometry>
    </visual>
    <collision>
      <origin xyz="0 0 0.035" rpy="-3.141592 0 0"/>
      <geometry>
        <cylinder radius="0.046" length="0.073"/>
      </geometry>
    </collision>
    <visual>
      <origin xyz="0 0 0.157" rpy="-3.141592 0 0"/>
      <geometry>
        <cylinder radius="0.038" length="0.186"/>
      </geometry>
    </visual>
    <collision>
      <origin xyz="0 0 0.157" rpy="-3.141592 0 0"/>
      <geometry>
        <cylinder radius="0.038" length="0.186"/>
      </geometry>
    </collision>
    <visual>
      <origin xyz="0 0 0" rpy="-1.570796 0 0"/>
      <geometry>
        <cylinder radius="0.046" length="0.119"/>
      </geometry>
    </visual>
    <collision>
      <origin xyz="0 0 0" rpy="-1.570796 0 0"/>
      <geometry>
        <cylinder radius="0.046" length="0.119"/>
      </geometry>
    </collision>
    <visual>
      <origin xyz="0 0.002 0.2435" rpy="-1.570796 0 0"/>
      <geometry>
        <cylinder radius="0.038" length="0.11"/>
      </geometry>
    </visual>
    <collision>
      <origin xyz="0 0.002 0.2435" rpy="-1.570796 0 0"/>
      <geometry>
        <cylinder radius="0.038" length="0.11"/>
      </geometry>
    </collision>
  </link>
  <joint name="elbow_joint" type="revolute">
    <parent link="upper_arm_link"/>
    <child link="forearm_link"/>
    <axis xyz="0 1 0"/>
    <limit effort="150" lower="-3.14159" upper="3.14159" velocity="3.14"/>
    <origin xyz="0 -0.093 0.244" rpy="0 -0.620011 0"/>
  </joint>
  <link name="forearm_link">
    <visual>
      <origin xyz="0 0 0.125" rpy="-3.141592 0 0"/>
      <geometry>
        <cylinder radius="0.032" length="0.18"/>
      </geometry>
    </visual>
    <collision>
      <origin xyz="0 0 0.125" rpy="-3.141592 0 0"/>
      <geometry>
        <cylinder radius="0.032" length="0.18"/>
      </geometry>
    </collision>
    <visual>
      <origin xyz="0 0.002 0.213" rpy="-1.570796 0 0"/>
      <geometry>
        <cylinder radius="0.032" length="0.1"/>
      </geometry>
    </visual>
    <collision>
      <origin xyz="0 0.002 0.213" rpy="-1.570796 0 0"/>
      <geometry>
        <cylinder radius="0.032" length="0.1"/>
      </geometry>
    </collision>
    <visual>
      <origin xyz="0 0.05 0" rpy="-1.570796 0 0"/>
      <geometry>
        <cylinder radius="0.037" length="0.05"/>
      </geometry>
    </visual>
    <collision>
      <origin xyz="0 0.05 0" rpy="-1.570796 0 0"/>
      <geometry>
        <cylinder radius="0.037" length="0.05"/>
      </geometry>
    </collision>
    <visual>
      <origin xyz="0 0.05 -0.025" rpy="-1.570796 0 0"/>
      <geometry>
        <sphere radius="0.037"/>
      </geometry>
    </visual>
    <collision>
      <origin xyz="0 0.05 -0.025" rpy="-1.570796 0 0"/>
      <geometry>
        <sphere radius="0.037"/>
      </geometry>
    </collision>
    <visual>
      <origin xyz="0 0.05 0.025" rpy="-1.570796 0 0"/>
      <geometry>
        <sphere radius="0.037"/>
      </geometry>
    </visual>
    <collision>
      <origin xyz="0 0.05 0.025" rpy="-1.570796 0 0"/>
      <geometry>
        <sphere radius="0.037"/>
      </geometry>
    </collision>
    <visual>
      <origin xyz="0 0 0.07" rpy="0 0 0"/>
      <geometry>
        <cylinder radius="0.03" length="0.1"/>
      </geometry>
    </visual>
    <collision>
      <origin xyz="0 0 0.07" rpy="0 0 0"/>
      <geometry>
        <cylinder radius="0.03" length="0.1"/>
      </geometry>
    </collision>
    <visual>
      <origin xyz="0 0.05 0.07" rpy="0 0 0"/>
      <geometry>
        <sphere radius="0.03"/>
      </geometry>
    </visual>
    <collision>
      <origin xyz="0 0.05 0.07" rpy="0 0 0"/>
      <geometry>
        <sphere radius="0.03"/>
      </geometry>
    </collision>
    <visual>
      <origin xyz="0 -0.05 0.07" rpy="0 0 0"/>
      <geometry>
        <sphere radius="0.03"/>
      </geometry>
    </visual>
    <collision>
      <origin xyz="0 -0.05 0.07" rpy="0 0 0"/>
      <geometry>
        <sphere radius="0.03"/>
      </geometry>
    </collision>
  </link>
  <joint name="wrist_1_joint" type="revolute">
    <parent link="forearm_link"/>
    <child link="wrist_1_link"/>
    <axis xyz="0 1 0"/>
    <limit effort="54" lower="-6.28319" upper="6.28319" velocity="6.28"/>
    <origin xyz="0 0 0.213" rpy="0 -0.359197 0"/>
  </joint>
  <link name="wrist_1_link">
    <visual>
      <origin xyz="0 0.075 0" rpy="-1.570796 0 0"/>
      <geometry>
        <cylinder radius="0.032" length="0.064"/>
      </geometry>
    </visual>
    <collision>
      <origin xyz="0 0.075 0" rpy="-1.570796 0 0"/>
      <geometry>
        <cylinder radius="0.032" length="0.064"/>
      </geometry>
    </collision>
    <visual>
      <origin xyz="0 0.104 0.003" rpy="3.141592 0 0"/>
      <geometry>
        <cylinder radius="0.033" length="0.1"/>
      </geometry>
    </visual>
    <collision>
      <origin xyz="0 0.104 0.003" rpy="3.141592 0 0"/>
      <geometry>
        <cylinder radius="0.033" length="0.1"/>
      </geometry>
    </collision>
  </link>
  <joint name="wrist_2_joint" type="revolute">
    <parent link="wrist_1_link"/>
    <child link="wrist_2_link"/>
    <axis xyz="0 0 1"/>
    <limit effort="54" lower="-6.28319" upper="6.28319" velocity="6.28"/>
    <origin xyz="0 0.104 0" rpy="0 0 0.990001"/>
  </joint>
  <link name="wrist_2_link">
    <visual>
      <origin xyz="0 0.002 0.0854" rpy="-1.570796 0 0"/>
      <geometry>
        <cylinder radius="0.032" length="0.097"/>
      </geometry>
    </visual>
    <collision>
      <origin xyz="0 0.002 0.0854" rpy="-1.570796 0 0"/>
      <geometry>
        <cylinder radius="0.032" length="0.097"/>
      </geometry>
    </collision>
    <visual>
      <origin xyz="0 0 0.0636" rpy="-3.141592 0 0"/>
      <geometry>
        <cylinder radius="0.032" length="0.043"/>
      </geometry>
    </visual>
    <collision>
      <origin xyz="0 0 0.0636" rpy="-3.141592 0 0"/>
      <geometry>
        <cylinder radius="0.032" length="0.043"/>
      </geometry>
    </collision>
  </link>
  <joint name="wrist_3_joint" type="revolute">
    <parent link="wrist_2_link"/>
    <child link="wrist_3_link"/>
    <axis xyz="0.00001 1 0.000035"/>
    <limit effort="54" lower="-6.28319" upper="6.28319" velocity="6.28"/>
    <origin xyz="0 0 0.085" rpy="3.141556 0.151562 3.141583"/>
  </joint>
  <link name="wrist_3_link">
    <visual>
      <origin xyz="-0.000137 0.069999 -0.000501" rpy="-1.570796 0 0"/>
      <geometry>
        <cylinder radius="0.032" length="0.044"/>
      </geometry>
    </visual>
    <collision>
      <origin xyz="-0.000137 0.069999 -0.000501" rpy="-1.570796 0 0"/>
      <geometry>
        <cylinder radius="0.032" length="0.044"/>
      </geometry>
    </collision>
  </link>
  <link name="ROBOTIQ 2F-85 Gripper">
    <visual>
      <origin xyz="-0.000137 -0.000001 0.016999" rpy="0 0 0"/>
      <geometry>
        <cylinder radius="0.038" length="0.035"/>
      </geometry>
    </visual>
    <collision>
      <origin xyz="-0.000137 -0.000001 0.016999" rpy="0 0 0"/>
      <geometry>
        <cylinder radius="0.038" length="0.035"/>
      </geometry>
    </collision>
    <visual>
      <origin xyz="-0.000137 -0.000001 0.053499" rpy="3.141593 1.570793 3.141593"/>
      <geometry>
        <cylinder radius="0.04" length="0.021"/>
      </geometry>
    </visual>
    <collision>
      <origin xyz="-0.000137 -0.000001 0.053499" rpy="3.141593 1.570793 3.141593"/>
      <geometry>
        <cylinder radius="0.04" length="0.021"/>
      </geometry>
    </collision>
  </link>
  <joint name="wrist_3_link_ROBOTIQ 2F-85 Gripper_joint" type="fixed">
    <parent link="wrist_3_link"/>
    <child link="ROBOTIQ 2F-85 Gripper"/>
    <origin xyz="-0.000137 0.089999 -0.000501" rpy="-1.5708 0 0"/>
  </joint>
  
  <link name="right inner knuckle">
    <visual>
      <origin xyz="0 0.037 0.0434" rpy="3.141593 1.570793 3.141593"/>
      <geometry>
        <cylinder radius="0.0026" length="0.027"/>
      </geometry>
    </visual>
    <collision>
      <origin xyz="0 0.037 0.0434" rpy="3.141593 1.570793 3.141593"/>
      <geometry>
        <cylinder radius="0.0026" length="0.027"/>
      </geometry>
    </collision>
    <visual>
      <origin xyz="0 0.0231 0.027" rpy="-0.7 0 0"/>
      <geometry>
        <box size="0.0152 0.0122 0.0072"/>
      </geometry>
    </visual>
    <collision>
      <origin xyz="0 0.0231 0.027" rpy="-0.7 0 0"/>
      <geometry>
        <box size="0.0152 0.0122 0.0072"/>
      </geometry>
    </collision>
    <visual>
      <origin xyz="0.00972 0.0308 0.0359" rpy="-0.7 0 0"/>
      <geometry>
        <box size="0.0046 0.0125 0.0307"/>
      </geometry>
    </visual>
    <collision>
      <origin xyz="0.00972 0.0308 0.0359" rpy="-0.7 0 0"/>
      <geometry>
        <box size="0.0046 0.0125 0.0307"/>
      </geometry>
    </collision>
    <visual>
      <origin xyz="-0.00972 0.0308 0.0359" rpy="-0.7 0 0"/>
      <geometry>
        <box size="0.0046 0.0125 0.0307"/>
      </geometry>
    </visual>
    <collision>
      <origin xyz="-0.00972 0.0308 0.0359" rpy="-0.7 0 0"/>
      <geometry>
        <box size="0.0046 0.0125 0.0307"/>
      </geometry>
    </collision>
    <visual>
      <origin xyz="-0.0145 0.016454 0.019218" rpy="-0.7 0 0"/>
      <geometry>
        <box size="0.005 0.0122 0.0288"/>
      </geometry>
    </visual>
    <collision>
      <origin xyz="-0.0145 0.016454 0.019218" rpy="-0.7 0 0"/>
      <geometry>
        <box size="0.005 0.0122 0.0288"/>
      </geometry>
    </collision>
    <visual>
      <origin xyz="0.0145 0.016454 0.019218" rpy="-0.7 0 0"/>
      <geometry>
        <box size="0.005 0.0122 0.0288"/>
      </geometry>
    </visual>
    <collision>
      <origin xyz="0.0145 0.016454 0.019218" rpy="-0.7 0 0"/>
      <geometry>
        <box size="0.005 0.0122 0.0288"/>
      </geometry>
    </collision>
    <visual>
      <origin xyz="-0.0157 0.001793 0.002019" rpy="-0.7 0 0"/>
      <geometry>
        <box size="0.0074 0.0122 0.0169"/>
      </geometry>
    </visual>
    <collision>
      <origin xyz="-0.0157 0.001793 0.002019" rpy="-0.7 0 0"/>
      <geometry>
        <box size="0.0074 0.0122 0.0169"/>
      </geometry>
    </collision>
    <visual>
      <origin xyz="0.0157 0.001793 0.002019" rpy="-0.7 0 0"/>
      <geometry>
        <box size="0.0074 0.0122 0.0169"/>
      </geometry>
    </visual>
    <collision>
      <origin xyz="0.0157 0.001793 0.002019" rpy="-0.7 0 0"/>
      <geometry>
        <box size="0.0074 0.0122 0.0169"/>
      </geometry>
    </collision>
  </link>
  <joint name="ROBOTIQ 2F-85 Gripper::right finger joint" type="revolute">
    <parent link="ROBOTIQ 2F-85 Gripper"/>
    <child link="right outer knuckle"/>
    <axis xyz="1 0 0"/>
    <limit effort="0.1" lower="0" upper="0.8" velocity="2"/>
    <origin xyz="0 0.030601 0.054904" rpy="0.8 0 0"/>
  </joint>
  <link name="right outer knuckle">
    <visual>
      <origin xyz="0 0 0" rpy="3.141593 1.570793 3.141593"/>
      <geometry>
        <cylinder radius="0.0076" length="0.011"/>
      </geometry>
    </visual>
    <collision>
      <origin xyz="0 0 0" rpy="3.141593 1.570793 3.141593"/>
      <geometry>
        <cylinder radius="0.0076" length="0.011"/>
      </geometry>
    </collision>
    <visual>
      <origin xyz="0 0.03142 -0.00405" rpy="3.141593 1.570793 3.141593"/>
      <geometry>
        <cylinder radius="0.006" length="0.011"/>
      </geometry>
    </visual>
    <collision>
      <origin xyz="0 0.03142 -0.00405" rpy="3.141593 1.570793 3.141593"/>
      <geometry>
        <cylinder radius="0.006" length="0.011"/>
      </geometry>
    </collision>
    <visual>
      <origin xyz="0 0.02474 0.00687" rpy="3.141593 1.570793 3.141593"/>
      <geometry>
        <cylinder radius="0.0025" length="0.024"/>
      </geometry>
    </visual>
    <collision>
      <origin xyz="0 0.02474 0.00687" rpy="3.141593 1.570793 3.141593"/>
      <geometry>
        <cylinder radius="0.0025" length="0.024"/>
      </geometry>
    </collision>
    <visual>
      <origin xyz="0 0.0281 0.0022" rpy="-0.12 0 0"/>
      <geometry>
        <box size="0.0091 0.02 0.0205"/>
      </geometry>
    </visual>
    <collision>
      <origin xyz="0 0.0281 0.0022" rpy="-0.12 0 0"/>
      <geometry>
        <box size="0.0091 0.02 0.0205"/>
      </geometry>
    </collision>
    <visual>
      <origin xyz="0 0.012 -0.0016" rpy="-0.12 0 0"/>
      <geometry>
        <box size="0.0091 0.012 0.009"/>
      </geometry>
    </visual>
    <collision>
      <origin xyz="0 0.012 -0.0016" rpy="-0.12 0 0"/>
      <geometry>
        <box size="0.0091 0.012 0.009"/>
      </geometry>
    </collision>
  </link>
  <link name="right outer finger">
    <visual>
      <origin xyz="0 0 0" rpy="3.141593 1.570793 3.141593"/>
      <geometry>
        <cylinder radius="0.0025" length="0.027"/>
      </geometry>
    </visual>
    <collision>
      <origin xyz="0 0 0" rpy="3.141593 1.570793 3.141593"/>
      <geometry>
        <cylinder radius="0.0025" length="0.027"/>
      </geometry>
    </collision>
    <visual>
      <origin xyz="0 0.0061 0.0472" rpy="3.141593 1.570793 3.141593"/>
      <geometry>
        <cylinder radius="0.0025" length="0.027"/>
      </geometry>
    </visual>
    <collision>
      <origin xyz="0 0.0061 0.0472" rpy="3.141593 1.570793 3.141593"/>
      <geometry>
        <cylinder radius="0.0025" length="0.027"/>
      </geometry>
    </collision>
    <visual>
      <origin xyz="0 0.003 0.0231" rpy="-0.13 0 0"/>
      <geometry>
        <box size="0.014 0.0124 0.0105"/>
      </geometry>
    </visual>
    <collision>
      <origin xyz="0 0.003 0.0231" rpy="-0.13 0 0"/>
      <geometry>
        <box size="0.014 0.0124 0.0105"/>
      </geometry>
    </collision>
    <visual>
      <origin xyz="-0.0095 0.0043 0.0355" rpy="-0.13 0 0"/>
      <geometry>
        <box size="0.005 0.0121 0.035"/>
      </geometry>
    </visual>
    <collision>
      <origin xyz="-0.0095 0.0043 0.0355" rpy="-0.13 0 0"/>
      <geometry>
        <box size="0.005 0.0121 0.035"/>
      </geometry>
    </collision>
    <visual>
      <origin xyz="0.0095 0.0043 0.0355" rpy="-0.13 0 0"/>
      <geometry>
        <box size="0.005 0.0121 0.035"/>
      </geometry>
    </visual>
    <collision>
      <origin xyz="0.0095 0.0043 0.0355" rpy="-0.13 0 0"/>
      <geometry>
        <box size="0.005 0.0121 0.035"/>
      </geometry>
    </collision>
    <visual>
      <origin xyz="0.0085 0.0007 0.0066" rpy="-0.13 0 0"/>
      <geometry>
        <box size="0.007 0.0121 0.025"/>
      </geometry>
    </visual>
    <collision>
      <origin xyz="0.0085 0.0007 0.0066" rpy="-0.13 0 0"/>
      <geometry>
        <box size="0.007 0.0121 0.025"/>
      </geometry>
    </collision>
    <visual>
      <origin xyz="-0.0085 0.0007 0.0066" rpy="-0.13 0 0"/>
      <geometry>
        <box size="0.007 0.0121 0.025"/>
      </geometry>
    </visual>
    <collision>
      <origin xyz="-0.0085 0.0007 0.0066" rpy="-0.13 0 0"/>
      <geometry>
        <box size="0.007 0.0121 0.025"/>
      </geometry>
    </collision>
  </link>
  <joint name="right outer knuckle_right outer finger_joint" type="fixed">
    <parent link="right outer knuckle"/>
    <child link="right outer finger"/>
    <origin xyz="0 0.0315 -0.0041" rpy="0 0 0"/>
  </joint>
  
  <link name="ROBOTIQ 2F-85 Gripper right inner finger">
    <visual>
      <origin xyz="0 0 0" rpy="3.141593 1.570793 3.141593"/>
      <geometry>
        <cylinder radius="0.006" length="0.015"/>
      </geometry>
    </visual>
    <collision>
      <origin xyz="0 0 0" rpy="3.141593 1.570793 3.141593"/>
      <geometry>
        <cylinder radius="0.006" length="0.015"/>
      </geometry>
    </collision>
    <visual>
      <origin xyz="0 -0.018 0.0065" rpy="3.141593 1.570793 3.141593"/>
      <geometry>
        <cylinder radius="0.006" length="0.015"/>
      </geometry>
    </visual>
    <collision>
      <origin xyz="0 -0.018 0.0065" rpy="3.141593 1.570793 3.141593"/>
      <geometry>
        <cylinder radius="0.006" length="0.015"/>
      </geometry>
    </collision>
    <visual>
      <origin xyz="0 -0.0086 0.0031" rpy="1.22 0 0"/>
      <geometry>
        <box size="0.014 0.012 0.019"/>
      </geometry>
    </visual>
    <collision>
      <origin xyz="0 -0.0086 0.0031" rpy="1.22 0 0"/>
      <geometry>
        <box size="0.014 0.012 0.019"/>
      </geometry>
    </collision>
    <visual>
      <origin xyz="0 -0.0179 0.01" rpy="0 0 0"/>
      <geometry>
        <box size="0.014 0.012 0.007"/>
      </geometry>
    </visual>
    <collision>
      <origin xyz="0 -0.0179 0.01" rpy="0 0 0"/>
      <geometry>
        <box size="0.014 0.012 0.007"/>
      </geometry>
    </collision>
    <visual>
      <origin xyz="0 -0.0155 0.029" rpy="0 0 0"/>
      <geometry>
        <box size="0.014 0.007 0.031"/>
      </geometry>
    </visual>
    <collision>
      <origin xyz="0 -0.0155 0.029" rpy="0 0 0"/>
      <geometry>
        <box size="0.014 0.007 0.031"/>
      </geometry>
    </collision>
  </link>
  <link name="right inner finger pad">
  </link>
  <joint name="ROBOTIQ 2F-85 Gripper right inner finger_right inner finger pad_joint" type="fixed">
    <parent link="ROBOTIQ 2F-85 Gripper right inner finger"/>
    <child link="right inner finger pad"/>
    <origin xyz="0 -0.02202 0.03242" rpy="-0.028 0 0"/>
  </joint>
 
  <link name="left inner knuckle">
    <visual>
      <origin xyz="0 0.037 0.0434" rpy="3.141593 1.570793 3.141593"/>
      <geometry>
        <cylinder radius="0.0026" length="0.027"/>
      </geometry>
    </visual>
    <collision>
      <origin xyz="0 0.037 0.0434" rpy="3.141593 1.570793 3.141593"/>
      <geometry>
        <cylinder radius="0.0026" length="0.027"/>
      </geometry>
    </collision>
    <visual>
      <origin xyz="0 0.0231 0.027" rpy="-0.7 0 0"/>
      <geometry>
        <box size="0.0152 0.0122 0.0072"/>
      </geometry>
    </visual>
    <collision>
      <origin xyz="0 0.0231 0.027" rpy="-0.7 0 0"/>
      <geometry>
        <box size="0.0152 0.0122 0.0072"/>
      </geometry>
    </collision>
    <visual>
      <origin xyz="0.00972 0.0308 0.0359" rpy="-0.7 0 0"/>
      <geometry>
        <box size="0.0046 0.0125 0.0307"/>
      </geometry>
    </visual>
    <collision>
      <origin xyz="0.00972 0.0308 0.0359" rpy="-0.7 0 0"/>
      <geometry>
        <box size="0.0046 0.0125 0.0307"/>
      </geometry>
    </collision>
    <visual>
      <origin xyz="-0.00972 0.0308 0.0359" rpy="-0.7 0 0"/>
      <geometry>
        <box size="0.0046 0.0125 0.0307"/>
      </geometry>
    </visual>
    <collision>
      <origin xyz="-0.00972 0.0308 0.0359" rpy="-0.7 0 0"/>
      <geometry>
        <box size="0.0046 0.0125 0.0307"/>
      </geometry>
    </collision>
    <visual>
      <origin xyz="-0.0145 0.016454 0.019218" rpy="-0.7 0 0"/>
      <geometry>
        <box size="0.005 0.0122 0.0288"/>
      </geometry>
    </visual>
    <collision>
      <origin xyz="-0.0145 0.016454 0.019218" rpy="-0.7 0 0"/>
      <geometry>
        <box size="0.005 0.0122 0.0288"/>
      </geometry>
    </collision>
    <visual>
      <origin xyz="0.0145 0.016454 0.019218" rpy="-0.7 0 0"/>
      <geometry>
        <box size="0.005 0.0122 0.0288"/>
      </geometry>
    </visual>
    <collision>
      <origin xyz="0.0145 0.016454 0.019218" rpy="-0.7 0 0"/>
      <geometry>
        <box size="0.005 0.0122 0.0288"/>
      </geometry>
    </collision>
    <visual>
      <origin xyz="-0.0157 0.001793 0.002019" rpy="-0.7 0 0"/>
      <geometry>
        <box size="0.0074 0.0122 0.0169"/>
      </geometry>
    </visual>
    <collision>
      <origin xyz="-0.0157 0.001793 0.002019" rpy="-0.7 0 0"/>
      <geometry>
        <box size="0.0074 0.0122 0.0169"/>
      </geometry>
    </collision>
    <visual>
      <origin xyz="0.0157 0.001793 0.002019" rpy="-0.7 0 0"/>
      <geometry>
        <box size="0.0074 0.0122 0.0169"/>
      </geometry>
    </visual>
    <collision>
      <origin xyz="0.0157 0.001793 0.002019" rpy="-0.7 0 0"/>
      <geometry>
        <box size="0.0074 0.0122 0.0169"/>
      </geometry>
    </collision>
  </link>
  <joint name="ROBOTIQ 2F-85 Gripper::left finger joint" type="revolute">
    <parent link="ROBOTIQ 2F-85 Gripper"/>
    <child link="left outer knuckle"/>
    <axis xyz="1 0 0"/>
    <limit effort="0.1" lower="0" upper="0.8" velocity="2"/>
    <origin xyz="0 -0.030601 0.054904" rpy="0.8 0 -3.141592"/>
  </joint>
  <link name="left outer knuckle">
    <visual>
      <origin xyz="0 0 0" rpy="3.141593 1.570793 3.141593"/>
      <geometry>
        <cylinder radius="0.0076" length="0.011"/>
      </geometry>
    </visual>
    <collision>
      <origin xyz="0 0 0" rpy="3.141593 1.570793 3.141593"/>
      <geometry>
        <cylinder radius="0.0076" length="0.011"/>
      </geometry>
    </collision>
    <visual>
      <origin xyz="0 0.03142 -0.00405" rpy="3.141593 1.570793 3.141593"/>
      <geometry>
        <cylinder radius="0.006" length="0.011"/>
      </geometry>
    </visual>
    <collision>
      <origin xyz="0 0.03142 -0.00405" rpy="3.141593 1.570793 3.141593"/>
      <geometry>
        <cylinder radius="0.006" length="0.011"/>
      </geometry>
    </collision>
    <visual>
      <origin xyz="0 0.02474 0.00687" rpy="3.141593 1.570793 3.141593"/>
      <geometry>
        <cylinder radius="0.0025" length="0.024"/>
      </geometry>
    </visual>
    <collision>
      <origin xyz="0 0.02474 0.00687" rpy="3.141593 1.570793 3.141593"/>
      <geometry>
        <cylinder radius="0.0025" length="0.024"/>
      </geometry>
    </collision>
    <visual>
      <origin xyz="0 0.0281 0.0022" rpy="-0.12 0 0"/>
      <geometry>
        <box size="0.0091 0.02 0.0205"/>
      </geometry>
    </visual>
    <collision>
      <origin xyz="0 0.0281 0.0022" rpy="-0.12 0 0"/>
      <geometry>
        <box size="0.0091 0.02 0.0205"/>
      </geometry>
    </collision>
    <visual>
      <origin xyz="0 0.012 -0.0016" rpy="-0.12 0 0"/>
      <geometry>
        <box size="0.0091 0.012 0.009"/>
      </geometry>
    </visual>
    <collision>
      <origin xyz="0 0.012 -0.0016" rpy="-0.12 0 0"/>
      <geometry>
        <box size="0.0091 0.012 0.009"/>
      </geometry>
    </collision>
  </link>
  <link name="left outer finger">
    <visual>
      <origin xyz="0 0 0" rpy="3.141593 1.570793 3.141593"/>
      <geometry>
        <cylinder radius="0.0025" length="0.027"/>
      </geometry>
    </visual>
    <collision>
      <origin xyz="0 0 0" rpy="3.141593 1.570793 3.141593"/>
      <geometry>
        <cylinder radius="0.0025" length="0.027"/>
      </geometry>
    </collision>
    <visual>
      <origin xyz="0 0.0061 0.0472" rpy="3.141593 1.570793 3.141593"/>
      <geometry>
        <cylinder radius="0.0025" length="0.027"/>
      </geometry>
    </visual>
    <collision>
      <origin xyz="0 0.0061 0.0472" rpy="3.141593 1.570793 3.141593"/>
      <geometry>
        <cylinder radius="0.0025" length="0.027"/>
      </geometry>
    </collision>
    <visual>
      <origin xyz="0 0.003 0.0231" rpy="-0.13 0 0"/>
      <geometry>
        <box size="0.014 0.0124 0.0105"/>
      </geometry>
    </visual>
    <collision>
      <origin xyz="0 0.003 0.0231" rpy="-0.13 0 0"/>
      <geometry>
        <box size="0.014 0.0124 0.0105"/>
      </geometry>
    </collision>
    <visual>
      <origin xyz="-0.0095 0.0043 0.0355" rpy="-0.13 0 0"/>
      <geometry>
        <box size="0.005 0.0121 0.035"/>
      </geometry>
    </visual>
    <collision>
      <origin xyz="-0.0095 0.0043 0.0355" rpy="-0.13 0 0"/>
      <geometry>
        <box size="0.005 0.0121 0.035"/>
      </geometry>
    </collision>
    <visual>
      <origin xyz="0.0095 0.0043 0.0355" rpy="-0.13 0 0"/>
      <geometry>
        <box size="0.005 0.0121 0.035"/>
      </geometry>
    </visual>
    <collision>
      <origin xyz="0.0095 0.0043 0.0355" rpy="-0.13 0 0"/>
      <geometry>
        <box size="0.005 0.0121 0.035"/>
      </geometry>
    </collision>
    <visual>
      <origin xyz="0.0085 0.0007 0.0066" rpy="-0.13 0 0"/>
      <geometry>
        <box size="0.007 0.0121 0.025"/>
      </geometry>
    </visual>
    <collision>
      <origin xyz="0.0085 0.0007 0.0066" rpy="-0.13 0 0"/>
      <geometry>
        <box size="0.007 0.0121 0.025"/>
      </geometry>
    </collision>
    <visual>
      <origin xyz="-0.0085 0.0007 0.0066" rpy="-0.13 0 0"/>
      <geometry>
        <box size="0.007 0.0121 0.025"/>
      </geometry>
    </visual>
    <collision>
      <origin xyz="-0.0085 0.0007 0.0066" rpy="-0.13 0 0"/>
      <geometry>
        <box size="0.007 0.0121 0.025"/>
      </geometry>
    </collision>
  </link>
  <joint name="left outer knuckle_left outer finger_joint" type="fixed">
    <parent link="left outer knuckle"/>
    <child link="left outer finger"/>
    <origin xyz="0 0.0315 -0.0041" rpy="0 0 0"/>
  </joint>

  <link name="ROBOTIQ 2F-85 Gripper left inner finger">
    <visual>
      <origin xyz="0 0 0" rpy="3.141593 1.570793 3.141593"/>
      <geometry>
        <cylinder radius="0.006" length="0.015"/>
      </geometry>
    </visual>
    <collision>
      <origin xyz="0 0 0" rpy="3.141593 1.570793 3.141593"/>
      <geometry>
        <cylinder radius="0.006" length="0.015"/>
      </geometry>
    </collision>
    <visual>
      <origin xyz="0 -0.018 0.0065" rpy="3.141593 1.570793 3.141593"/>
      <geometry>
        <cylinder radius="0.006" length="0.015"/>
      </geometry>
    </visual>
    <collision>
      <origin xyz="0 -0.018 0.0065" rpy="3.141593 1.570793 3.141593"/>
      <geometry>
        <cylinder radius="0.006" length="0.015"/>
      </geometry>
    </collision>
    <visual>
      <origin xyz="0 -0.0086 0.0031" rpy="1.22 0 0"/>
      <geometry>
        <box size="0.014 0.012 0.019"/>
      </geometry>
    </visual>
    <collision>
      <origin xyz="0 -0.0086 0.0031" rpy="1.22 0 0"/>
      <geometry>
        <box size="0.014 0.012 0.019"/>
      </geometry>
    </collision>
    <visual>
      <origin xyz="0 -0.0179 0.01" rpy="0 0 0"/>
      <geometry>
        <box size="0.014 0.012 0.007"/>
      </geometry>
    </visual>
    <collision>
      <origin xyz="0 -0.0179 0.01" rpy="0 0 0"/>
      <geometry>
        <box size="0.014 0.012 0.007"/>
      </geometry>
    </collision>
    <visual>
      <origin xyz="0 -0.0155 0.029" rpy="0 0 0"/>
      <geometry>
        <box size="0.014 0.007 0.031"/>
      </geometry>
    </visual>
    <collision>
      <origin xyz="0 -0.0155 0.029" rpy="0 0 0"/>
      <geometry>
        <box size="0.014 0.007 0.031"/>
      </geometry>
    </collision>
  </link>
  <link name="left inner finger pad">
  </link>
  <joint name="ROBOTIQ 2F-85 Gripper left inner finger_left inner finger pad_joint" type="fixed">
    <parent link="ROBOTIQ 2F-85 Gripper left inner finger"/>
    <child link="left inner finger pad"/>
    <origin xyz="0 -0.02202 0.03242" rpy="-0.028 0 0"/>
  </joint>
</robot>
